Traceback (most recent call last):
  File "/nix/store/ria264d36cmhxik90bmzwi12s7nll1y3-python3.8-nbclient-0.5.3/lib/python3.8/site-packages/nbclient/client.py", line 622, in _async_poll_for_reply
    msg = await ensure_async(self.kc.shell_channel.get_msg(timeout=new_timeout))
  File "/nix/store/ria264d36cmhxik90bmzwi12s7nll1y3-python3.8-nbclient-0.5.3/lib/python3.8/site-packages/nbclient/util.py", line 85, in ensure_async
    result = await obj
  File "/nix/store/9b9cv8mvnxbzyf5rxs1jgw5fwpnq0a42-python3.8-jupyter_client-6.1.12/lib/python3.8/site-packages/jupyter_client/asynchronous/channels.py", line 48, in get_msg
    raise Empty
_queue.Empty

During handling of the above exception, another exception occurred:

Traceback (most recent call last):
  File "/nix/store/qrkgxqbbr00qjik2rfqdw3z8a062s3ls-python3.8-jupyter-cache-0.4.2/lib/python3.8/site-packages/jupyter_cache/executors/utils.py", line 51, in single_nb_execution
    executenb(
  File "/nix/store/ria264d36cmhxik90bmzwi12s7nll1y3-python3.8-nbclient-0.5.3/lib/python3.8/site-packages/nbclient/client.py", line 1112, in execute
    return NotebookClient(nb=nb, resources=resources, km=km, **kwargs).execute()
  File "/nix/store/ria264d36cmhxik90bmzwi12s7nll1y3-python3.8-nbclient-0.5.3/lib/python3.8/site-packages/nbclient/util.py", line 74, in wrapped
    return just_run(coro(*args, **kwargs))
  File "/nix/store/ria264d36cmhxik90bmzwi12s7nll1y3-python3.8-nbclient-0.5.3/lib/python3.8/site-packages/nbclient/util.py", line 53, in just_run
    return loop.run_until_complete(coro)
  File "/nix/store/4s0h5aawbap3xhldxhcijvl26751qrjr-python3-3.8.9/lib/python3.8/asyncio/base_events.py", line 616, in run_until_complete
    return future.result()
  File "/nix/store/ria264d36cmhxik90bmzwi12s7nll1y3-python3.8-nbclient-0.5.3/lib/python3.8/site-packages/nbclient/client.py", line 553, in async_execute
    await self.async_execute_cell(
  File "/nix/store/ria264d36cmhxik90bmzwi12s7nll1y3-python3.8-nbclient-0.5.3/lib/python3.8/site-packages/nbclient/client.py", line 841, in async_execute_cell
    exec_reply = await self.task_poll_for_reply
  File "/nix/store/ria264d36cmhxik90bmzwi12s7nll1y3-python3.8-nbclient-0.5.3/lib/python3.8/site-packages/nbclient/client.py", line 646, in _async_poll_for_reply
    await self._async_handle_timeout(timeout, cell)
  File "/nix/store/ria264d36cmhxik90bmzwi12s7nll1y3-python3.8-nbclient-0.5.3/lib/python3.8/site-packages/nbclient/client.py", line 696, in _async_handle_timeout
    raise CellTimeoutError.error_from_timeout_and_cell(
nbclient.exceptions.CellTimeoutError: A cell timed out while it was being executed, after 30 seconds.
The message was: Cell execution timed out.
Here is a preview of the cell contents:
-------------------
["population = bpd.read_csv('../../data/salaries.csv', names=['Salary'])", "pop_median = population.get('Salary').median()", '', 'interval_lowers = []', 'interval_uppers = []']
...
['    lower = np.percentile(boot_medians, 2.5)', '    upper = np.percentile(boot_medians, 97.5)', '    ', '    interval_lowers.append(lower)', '    interval_uppers.append(upper)']
-------------------

